Workbook

Sheet Trade Log
A1: DATE | B1: Previous Trade Loss | C1: Day of Week | D1: NY/LO Hours | E1: TOKEN | F1: Major News passed hour | G1: LONG/ SHORT | H1: Trend Break | I1: Wave2 at | J1: Wave3 at | K1: Highlight on Wave3 | L1: Wave4 at | M1: Wave 4 End at wave 1 end | N1: Wave5 at | O1: Highlight on Wave5 | P1: RSI Divergences betweem 3 & 5 | Q1: SMOG - SMOG Indicator at Wave 5 | R1: SMOG - COCH/BOS Between Wave 5 & A | S1: SMOG - COCH/BOS After Wave A | T1: SMOG - Bear Short / Bull Long FVG on Wave A | U1: Wave A beyond 3 and not passed 4 | V1: Wave C at | W1: P/ L/ BE | X1: Profit passed 1:3RR | Y1: P&L | Z1: ACCOUNT SIZE | AA1: P&L % | AB1: CHART | AC1: Average PNL | AD1: Account Growth
A2: SUI - 26/05/04 7:30 | E2: - | G2: - | Y2: - | Z2: 100 | AA2: {=INDEX(Z:Z,COUNTA(Z:Z))*0.02} -> 3.9564 | AB2: - | AC2: =AVERAGE(AA8:AA112) -> 0.018947131 | AD2: =((SUM(Y:Y)/Z2)) -> 0.9782 | AE2: =((SUM(Y:Y)+Z2)/Z2) -> 1.9782
A3: 26/05/15 | B3: No | C3: FRI | D3: LO | E3: ETH | F3: No | G3: LONG | H3: Yes | I3: 0.786 | J3: 2.618 | K3: No | L3: 0.382 | M3: Before | N3: 3.618 | O3: Yes | P3: No | Q3: Yes | R3: No | S3: CHoCH | T3: Yes | U3: Yes | V3: No | W3: L | X3: Yes | Y3: =IF(Z3="","",Z3-Z2) -> -2 | Z3: =Z2-2 -> 98 | AA3: =IF(ISBLANK(Z3),,Y3/Z2) -> -0.02
A4: 26/05/25 | B4: No | C4: MON | D4: NY | E4: AVAX | F4: No | G4: SHORT | H4: Yes | I4: 0.5 | J4: 1.618 | K4: Yes | L4: 0.236 | M4: Before | N4: 2.618 | O4: Yes | P4: No | Q4: Yes | R4: CHoCH | S4: CHoCH | T4: Yes | U4: Yes | V4: 1.618 | W4: P | X4: Yes | Y4: =IF(Z4="","",Z4-Z3) -> 5.03 | Z4: =Z3+5.03 -> 103.03 | AA4: =IF(ISBLANK(Z4),,Y4/Z3) -> 0.051326531
A5: 26/06/05 | B5: No | C5: FRI | D5: LO | E5: AVAX | F5: Yes | G5: LONG | H5: No | I5: 0.382 | J5: No | K5: Yes | L5: 0.5 | M5: At | N5: 2.618 | O5: Yes | P5: Yes | Q5: Yes | R5: No | S5: No | T5: Yes | U5: Yes | V5: No | W5: L | X5: No | Y5: =IF(Z5="","",Z5-Z4) -> -1 | Z5: =Z4-1 -> 102.03 | AA5: =IF(ISBLANK(Z5),,Y5/Z4) -> -0.0097059109 | AC5: When Price cross Wave A - Move SL to below Wave B
A6: 26/06/07 | B6: No | C6: THU | D6: LO | E6: ADA | F6: No | G6: SHORT | H6: No | I6: 0.382 | J6: 2.618 | K6: Yes | L6: 0.382 | M6: Before | N6: 4.618 | O6: Yes | P6: Yes | Q6: Yes | R6: CHoCH | S6: No | T6: Yes | U6: Yes | V6: 1.618 | W6: L | X6: No | Y6: =IF(Z6="","",Z6-Z5) -> -0.63 | Z6: =Z5-0.63 -> 101.4 | AA6: =IF(ISBLANK(Z6),,Y6/Z5) -> -0.0061746545 | AC6: When Price cross Wave C - Move SL to last CHoCH/BOS LL/HH in the direction of trend
A7: 26/06/08 | B7: No | C7: MON | D7: LO | E7: ETH | F7: No | G7: SHORT | H7: Yes | I7: 0.5 | J7: 1.618 | K7: Yes | L7: 0.382 | M7: Before | N7: 2.618 | O7: Yes | P7: No | Q7: Yes | R7: No | S7: BOS | T7: Yes | U7: Yes | V7: 1 | W7: P | X7: Yes | Y7: =IF(Z7="","",Z7-Z6) -> 3.9 | Z7: =Z6+3.9 -> 105.3 | AA7: =IF(ISBLANK(Z7),,Y7/Z3) -> 0.039795918
A8: 26/06/14 | B8: No | C8: SUN | D8: NY | E8: SOL | F8: No | G8: LONG | H8: Yes | I8: 0.5 | J8: 1.618 | K8: No | L8: 0.5 | M8: At | N8: 2.618 | O8: Yes | P8: No | Q8: Yes | R8: No | S8: CHoCH | T8: No | U8: No | V8: 1.618 | W8: P | X8: Yes | Y8: =IF(Z8="","",Z8-Z7) -> 8.04 | Z8: =Z7+8.04 -> 113.34 | AA8: =IF(ISBLANK(Z8),,Y8/Z2) -> 0.0804
A9: 26/06/16 | B9: No | C9: TUE | D9: NY | E9: ADA | F9: No | G9: LONG | H9: Yes | I9: 0.236 | J9: 3.618 | K9: No | L9: 0.382 | M9: Before | N9: 4.618 | O9: Yes | P9: No | Q9: Yes | R9: CHoCH | S9: No | T9: Yes | U9: Yes | V9: 1.618 | W9: L | X9: No | Y9: =IF(Z9="","",Z9-Z8) -> -2.23 | Z9: =Z8-2.23 -> 111.11 | AA9: =IF(ISBLANK(Z9),,Y9/Z3) -> -0.022755102
A10: 26/06/24 | B10: No | C10: WED | D10: LOP | E10: SOL | F10: No | G10: LONG | H10: Yes | I10: 0.5 | J10: 1.618 | K10: No | L10: 0.382 | M10: Before | N10: 2.618 | O10: Yes | P10: No | Q10: Yes | R10: No | S10: No | T10: No | U10: No | V10: 1.618 | W10: P | X10: No | Y10: =IF(Z10="","",Z10-Z9) -> 5.94 | Z10: =Z9+5.94 -> 117.05 | AA10: =IF(ISBLANK(Z10),,Y10/Z8) -> 0.052408682
A11: 26/06/22 | B11: No | C11: MON | D11: LOP | E11: ZECUS | F11: No | G11: LONG | H11: Yes | I11: 0.618 | J11: No | K11: Yes | L11: 0.5 | M11: Before | N11: No | O11: Yes | P11: Yes | Q11: Yes | R11: No | S11: CHoCH | T11: Yes | U11: Yes | V11: 1.618 | W11: P | X11: No | Y11: =IF(Z11="","",Z11-Z10) -> 5.2 | Z11: =Z10+5.2 -> 122.25 | AA11: =IF(ISBLANK(Z11),,Y11/Z10) -> 0.044425459
A12: 26/06/23 | B12: No | C12: TUE | D12: LO | E12: BNB | F12: No | G12: LONG | H12: Yes | I12: No | J12: 1.618 | K12: Yes | L12: 0.382 | M12: Before | N12: No | O12: Yes | P12: Yes | Q12: No | R12: No | S12: CHoCH | T12: No | U12: No | V12: No | W12: P | X12: Yes | Y12: =IF(Z12="","",Z12-Z11) -> 4.4 | Z12: =Z11+4.4 -> 126.65 | AA12: =IF(ISBLANK(Z12),,Y12/Z11) -> 0.03599182
A13: 26/06/25 | B13: No | C13: THU | D13: NY | E13: BNB | F13: Yes | G13: LONG | H13: Yes | I13: 0.786 | J13: No | K13: Yes | L13: 0.5 | M13: Before | N13: No | O13: Yes | P13: Yes | Q13: Yes | R13: CHoCH | S13: CHoCH | T13: Yes | U13: Yes | V13: No | W13: L | X13: No | Y13: =IF(Z13="","",Z13-Z12) -> -2.53 | Z13: =Z12-2.53 -> 124.12 | AA13: =IF(ISBLANK(Z13),,Y13/Z12) -> -0.019976313
A14: 26/06/30 | B14: No | C14: TUE | D14: NY | E14: ADA | F14: Yes | G14: LONG | H14: Yes | I14: 0.236 | J14: 1.618 | K14: Yes | L14: 0.5 | M14: Before | N14: 3.618 | O14: Yes | P14: No | Q14: Yes | R14: No | S14: CHoCH | T14: Yes | U14: Yes | V14: 1.618 | W14: L | X14: No | Y14: =IF(Z14="","",Z14-Z13) -> -0.65 | Z14: =Z13-0.65 -> 123.47 | AA14: =IF(ISBLANK(Z14),,Y14/Z13) -> -0.0052368675
A15: 26/07/01 | B15: No | C15: WED | D15: LOP | E15: AVAX | F15: No | G15: LONG | H15: Yes | I15: 0.618 | J15: 1.618 | K15: No | L15: 0.5 | M15: At | N15: 2.618 | O15: Yes | P15: No | Q15: Yes | R15: No | S15: CHoCH | T15: Yes | U15: Yes | V15: 0.618 | W15: P | X15: Yes | Y15: =IF(Z15="","",Z15-Z14) -> 5.55 | Z15: =Z14+5.55 -> 129.02 | AA15: =IF(ISBLANK(Z15),,Y15/Z13) -> 0.044714792
A16: 26/07/01 | B16: No | C16: WED | D16: LOP | E16: SOL | F16: No | G16: SHORT | H16: Yes | I16: 0.786 | J16: No | K16: Yes | L16: 0.5 | M16: Before | N16: 2.618 | O16: No | P16: Yes | Q16: Yes | R16: CHoCH | S16: BOS | T16: Yes | U16: Yes | V16: No | W16: L | X16: No | Y16: =IF(Z16="","",Z16-Z15) -> -2.58 | Z16: =Z15-2.58 -> 126.44 | AA16: =IF(ISBLANK(Z16),,Y16/Z13) -> -0.020786336
A17: 26/07/01 | B17: Yes | C17: WED | D17: NY | E17: XLM | F17: No | G17: SHORT | H17: Yes | I17: 0.618 | J17: 1.618 | K17: Yes | L17: 0.382 | M17: Before | N17: 2.618 | O17: Yes | P17: No | Q17: Yes | R17: No | S17: CHoCH | T17: No | U17: Yes | V17: No | W17: P | X17: No | Y17: =IF(Z17="","",Z17-Z16) -> 0.39 | Z17: =Z16+0.39 -> 126.83 | AA17: =IF(ISBLANK(Z17),,Y17/Z16) -> 0.0030844669
A18: 26/07/03 | B18: No | C18: FRI | D18: LO | E18: ZECUS | F18: No | G18: SHORT | H18: Yes | I18: No | J18: 1.618 | K18: Yes | L18: 0.236 | M18: Before | N18: 2.618 | O18: Yes | P18: No | Q18: Yes | R18: CHoCH | S18: No | T18: Yes | U18: Yes | V18: No | W18: L | X18: No | Y18: =IF(Z18="","",Z18-Z17) -> -2.54 | Z18: =Z17-2.54 -> 124.29 | AA18: =IF(ISBLANK(Z18),,Y18/Z17) -> -0.020026808
A19: 26/07/05 | B19: No | C19: SUN | D19: LOP | E19: DOGE | F19: No | G19: SHORT | H19: Yes | I19: 0.382 | J19: 1.618 | K19: Yes | L19: 0.382 | M19: Before | N19: 2.618 | O19: Yes | P19: Yes | Q19: Yes | R19: CHoCH | S19: CHoCH | T19: Yes | U19: Yes | V19: 0.618 | W19: P | X19: Yes | Y19: =IF(Z19="","",Z19-Z18) -> 12.58 | Z19: =Z18+12.58 -> 136.87 | AA19: =IF(ISBLANK(Z19),,Y19/Z18) -> 0.1012149
A20: 26/07/06 | B20: No | C20: MON | D20: LO | E20: LINK | F20: Yes | G20: SHORT | H20: Yes | I20: 0.618 | J20: No | K20: Yes | L20: 0.382 | M20: Before | N20: 2.618 | O20: Yes | P20: No | Q20: Yes | R20: CHoCH | S20: CHoCH | T20: Yes | U20: Yes | V20: No | W20: L | X20: No | Y20: =IF(Z20="","",Z20-Z19) -> -1.23 | Z20: =Z19-1.23 -> 135.64 | AA20: =IF(ISBLANK(Z20),,Y20/Z19) -> -0.0089866296
A21: 26/07/06 | B21: Yes | C21: MON | D21: LO | E21: DOGE | F21: Yes | G21: SHORT | H21: Yes | I21: 0.382 | J21: 1.618 | K21: Yes | L21: 0.382 | M21: Before | N21: 2.618 | O21: Yes | P21: No | Q21: Yes | R21: CHoCH | S21: CHoCH | T21: Yes | U21: Yes | V21: No | W21: P | X21: Yes | Y21: =IF(Z21="","",Z21-Z20) -> 1.74 | Z21: =Z20+1.74 -> 137.38 | AA21: =IF(ISBLANK(Z21),,Y21/Z20) -> 0.012828074
A22: 26/07/07 | B22: No | C22: TUE | D22: LO | E22: ADA | F22: No | G22: LONG | H22: No | I22: 0.5 | J22: 2.618 | K22: No | L22: 0.236 | M22: Before | N22: 3.618 | O22: Yes | P22: No | Q22: Yes | R22: No | S22: No | T22: Yes | U22: Yes | V22: No | W22: L | X22: No | Y22: =IF(Z22="","",Z22-Z21) -> -2.75 | Z22: =Z21-2.75 -> 134.63 | AA22: =IF(ISBLANK(Z22),,Y22/Z21) -> -0.02001747
A23: 26/07/09 | B23: No | C23: THU | D23: LOP | E23: ETH | F23: No | G23: LONG | H23: Yes | I23: 0.618 | J23: 2.618 | K23: Yes | L23: 0.382 | M23: Before | N23: 2.618 | O23: Yes | P23: No | Q23: Yes | R23: No | S23: CHoCH | T23: No | U23: Yes | V23: 1.618 | W23: P | X23: Yes | Y23: =IF(Z23="","",Z23-Z22) -> 8.76 | Z23: =Z22+8.76 -> 143.39 | AA23: =IF(ISBLANK(Z23),,Y23/Z22) -> 0.065067221
A24: 26/07/14 | B24: No | C24: TUE | D24: NY | E24: SOL | F24: Yes | G24: SHORT | H24: Yes | I24: 0.382 | J24: 2.618 | K24: Yes | L24: 0.382 | M24: Before | N24: 2.618 | O24: Yes | P24: Yes | Q24: No | R24: No | S24: No | T24: No | U24: Yes | V24: 1.618 | W24: L | X24: No | Y24: =IF(Z24="","",Z24-Z23) -> 2.87 | Z24: =Z23+2.87 -> 146.26 | AA24: =IF(ISBLANK(Z24),,Y24/Z23) -> 0.020015343
A25: 26/07/14 | B25: No | C25: TUE | D25: NY | E25: SUI | F25: Yes | G25: SHORT | H25: Yes | I25: 0.786 | J25: 1.618 | K25: Yes | L25: 0.382 | M25: Before | N25: 3.618 | O25: Yes | P25: Yes | Q25: Yes | R25: No | S25: CHoCH | T25: Yes | U25: No | V25: 2.618 | W25: L | X25: No | Y25: =IF(Z25="","",Z25-Z24) -> -2.05 | Z25: =Z24-2.05 -> 144.21 | AA25: =IF(ISBLANK(Z25),,Y25/Z24) -> -0.014016136
A26: 26/07/15 | B26: No | C26: WED | D26: LO | E26: XRP | F26: Yes | G26: SHORT | H26: Yes | I26: 0.5 | J26: 2.618 | K26: Yes | L26: 0.236 | M26: Before | N26: 3.618 | O26: Yes | P26: Yes | Q26: Yes | R26: CHoCH | S26: No | T26: No | U26: Yes | V26: 0.618 | W26: L | X26: No | Y26: =IF(Z26="","",Z26-Z25) -> -2.88 | Z26: =Z25-2.88 -> 141.33 | AA26: =IF(ISBLANK(Z26),,Y26/Z25) -> -0.019970876
A27: 26/07/15 | B27: Yes | C27: WED | D27: NY | E27: LINK | F27: Yes | G27: SHORT | H27: Yes | I27: 0.618 | J27: No | K27: Yes | L27: 0.382 | M27: Before | N27: 4.618 | O27: Yes | P27: Yes | Q27: No | R27: No | S27: CHoCH | T27: Yes | U27: No | V27: 2.618 | W27: P | X27: Yes | Y27: =IF(Z27="","",Z27-Z26) -> 18.08 | Z27: =Z26+18.08 -> 159.41 | AA27: =IF(ISBLANK(Z27),,Y27/Z26) -> 0.12792755
A28: 26/07/17 | B28: No | C28: FRI | D28: LO | E28: HYPE | F28: Yes | G28: LONG | H28: Yes | I28: 0.618 | J28: No | K28: Yes | L28: 0.236 | M28: Before | N28: 3.618 | O28: Yes | P28: Yes | Q28: Yes | R28: CHoCH | S28: No | T28: Yes | U28: No | V28: No | W28: P | X28: No | Y28: =IF(Z28="","",Z28-Z27) -> 9.56 | Z28: =Z27+9.56 -> 168.97 | AA28: =IF(ISBLANK(Z28),,Y28/Z27) -> 0.059971144
A29: 26/07/19 | B29: No | C29: SUN | D29: NY | E29: AVAX | F29: No | G29: LONG | H29: Yes | I29: 0.618 | J29: 1.618 | K29: Yes | L29: No | M29: Before | N29: 2.618 | O29: Yes | P29: No | Q29: Yes | R29: No | S29: No | T29: No | U29: No | V29: 0.618 | W29: L | X29: No | Y29: =IF(Z29="","",Z29-Z28) -> -2.16 | Z29: =Z28-2.16 -> 166.81 | AA29: =IF(ISBLANK(Z29),,Y29/Z28) -> -0.012783334
A30: 26/07/19 | B30: Yes | C30: SUN | D30: NY | E30: SUI | F30: No | G30: SHORT | H30: Yes | I30: 0.382 | J30: 1.618 | K30: No | L30: No | M30: After | N30: 2.618 | O30: Yes | P30: Yes | Q30: Yes | R30: BOS | S30: No | T30: No | U30: Yes | V30: 0.618 | W30: L | X30: No | Y30: =IF(Z30="","",Z30-Z29) -> -3.34 | Z30: =Z29-3.34 -> 163.47 | AA30: =IF(ISBLANK(Z30),,Y30/Z29) -> -0.02002278
A31: 26/07/20 | B31: No | C31: MON | D31: LO | E31: ZEC | F31: No | G31: LONG | H31: Yes | I31: 0.618 | J31: 1.618 | K31: No | L31: No | M31: After | N31: 2.618 | O31: No | P31: Yes | Q31: Yes | R31: CHoCH | S31: No | T31: Yes | U31: No | V31: 1.618 | W31: P | X31: Yes | Y31: =IF(Z31="","",Z31-Z30) -> 10.56 | Z31: =Z30+10.56 -> 174.03 | AA31: =IF(ISBLANK(Z31),,Y31/Z30) -> 0.064599009
A32: 26/07/20 | B32: No | C32: MON | D32: LO | E32: LINK | F32: No | G32: SHORT | H32: Yes | I32: 0.382 | J32: 1.618 | K32: No | L32: 0.382 | M32: Before | N32: No | O32: Yes | P32: No | Q32: Yes | R32: CHoCH | S32: No | T32: Yes | U32: Yes | V32: 0.618 | W32: L | X32: No | Y32: =IF(Z32="","",Z32-Z31) -> -3.48 | Z32: =Z31-3.48 -> 170.55 | AA32: =IF(ISBLANK(Z32),,Y32/Z31) -> -0.019996552
A33: 26/07/21 | B33: No | C33: TUE | D33: LOP | E33: ADA | F33: Yes | G33: SHORT | H33: Yes | I33: 0.236 | J33: 1.618 | K33: No | L33: 0.382 | M33: Before | N33: 2.618 | O33: Yes | P33: No | Q33: Yes | R33: No | S33: CHoCH | T33: No | U33: No | V33: 1.618 | W33: P | X33: No | Y33: =IF(Z33="","",Z33-Z32) -> 0.34 | Z33: =Z32+0.34 -> 170.89 | AA33: =IF(ISBLANK(Z33),,Y33/Z32) -> 0.0019935503
A34: 26/07/21 | B34: No | C34: TUE | D34: LO | E34: ADA | F34: No | G34: SHORT | H34: Yes | I34: 0.236 | J34: 1.618 | K34: No | L34: 0.382 | M34: At | N34: 2.618 | O34: Yes | P34: No | Q34: Yes | R34: No | S34: CHoCH | T34: No | U34: No | V34: 2.618 | W34: P | X34: No | Y34: =IF(Z34="","",Z34-Z33) -> 10.49 | Z34: =Z33+10.49 -> 181.38 | AA34: =IF(ISBLANK(Z34),,Y34/Z33) -> 0.061384516
A35: 26/07/22 | B35: Yes | C35: WED | D35: LO | E35: HYPE | F35: No | G35: LONG | H35: Yes | I35: 0.236 | J35: 1.618 | K35: Yes | L35: No | M35: At | N35: 2.618 | O35: Yes | P35: Yes | Q35: No | R35: No | S35: No | T35: No | U35: No | V35: 1.618 | W35: L | X35: No | Y35: =IF(Z35="","",Z35-Z34) -> -0.94 | Z35: =Z34-0.94 -> 180.44 | AA35: =IF(ISBLANK(Z35),,Y35/Z34) -> -0.0051824898
A36: 26/07/24 | B36: No | C36: FRI | D36: LO | E36: ADA | F36: Yes | G36: LONG | H36: Yes | I36: 0.5 | J36: 1.618 | K36: Yes | L36: 0.236 | M36: Before | N36: No | O36: Yes | P36: Yes | Q36: Yes | R36: No | S36: No | T36: No | U36: Yes | V36: 2.618 | W36: L | X36: No | Y36: =IF(Z36="","",Z36-Z35) -> -3.59 | Z36: =Z35-3.59 -> 176.85 | AA36: =IF(ISBLANK(Z36),,Y36/Z35) -> -0.01989581
A37: 26/07/26 | B37: No | C37: SUN | D37: NY | E37: SUI | F37: No | G37: SHORT | H37: Yes | I37: 0.618 | J37: 2.618 | K37: Yes | L37: No | M37: Before | N37: 4.618 | O37: Yes | P37: Yes | Q37: Yes | R37: CHoCH | S37: BOS | T37: Yes | U37: Yes | V37: 1.618 | W37: P | X37: No | Y37: =IF(Z37="","",Z37-Z36) -> 1.57 | Z37: =Z36+1.57 -> 178.42 | AA37: =IF(ISBLANK(Z37),,Y37/Z36) -> 0.0088775799
A38: 26/07/31 | B38: No | C38: FRI | D38: LOP | E38: HYPE | F38: Yes | G38: SHORT | H38: Yes | I38: 0.236 | J38: No | K38: Yes | L38: 0.236 | M38: At | N38: 4.618 | O38: Yes | P38: No | Q38: Yes | R38: CHoCH | S38: BOS | T38: Yes | U38: No | V38: 1.618 | W38: P | X38: No | Y38: =IF(Z38="","",Z38-Z37) -> 4.18 | Z38: =Z37+4.18 -> 182.6 | AA38: =IF(ISBLANK(Z38),,Y38/Z37) -> 0.023427867
A39: 26/08/01 | B39: No | C39: SAT | D39: LO | E39: LINK | F39: No | G39: LONG | H39: Yes | I39: No | J39: 2.618 | K39: No | L39: 0.382 | M39: Before | N39: 4.618 | O39: Yes | P39: No | Q39: Yes | R39: CHoCH | S39: No | T39: No | U39: Yes | V39: 1.618 | W39: L | X39: No | Y39: =IF(Z39="","",Z39-Z38) -> -3.65 | Z39: =Z38-3.65 -> 178.95 | AA39: =IF(ISBLANK(Z39),,Y39/Z38) -> -0.019989047
A40: 26/08/03 | B40: No | C40: MON | D40: LO | E40: ETH | F40: Yes | G40: LONG | H40: Yes | I40: 0.786 | J40: 2.618 | K40: Yes | L40: 0.382 | M40: Before | N40: 3.618 | O40: Yes | P40: No | Q40: Yes | R40: No | S40: No | T40: Yes | U40: Yes | V40: 2.618 | W40: P | X40: Yes | Y40: =IF(Z40="","",Z40-Z39) -> 6.22 | Z40: =Z39+6.22 -> 185.17 | AA40: =IF(ISBLANK(Z40),,Y40/Z39) -> 0.034758312
...

Sheet Sheet15
A1: PROMP: Analyse Trade Log
A2: As a crypto trading analyst, use the Trade Log sheet to analyse which Trend Break / Elliott Wave / Fibonacci setup combinations produce the most profitable trades. Treat columns B:V and X as setup variables, column W as result (P/L/BE), and column Y as actual P&L. Include all rows with setup data and usable P&L. Rank setups by total P&L, average P&L, win rate, and consistency. Build a new analysis dashboard sheet with: overall KPIs, key findings, top complete setup signatures, top repeated setup factors, best value per setup column, and charts. State the row coverage and any data limitations.
A4: PROMP: Analyse Market for Trade | E4: https://chatgpt.com/g/g-p-6a577a0a16988191938b9fe7ef54618a-crypto-futures-trading-command-center/project
A5: Trading Method: 35A Token: ETH Direction: LONG Current Open Positions: None
A6: Also Attach TradingView ScreenShot

Sheet Do Not Delete or Edit
L2: % TP
L3: =abs(1-('TCL 5 Limit'!C7/'TCL 5 Limit'!C5)) -> #REF! | M3: =L3*B11 -> #REF! | R3: Margin Available
F4: 1 | O4: =ABS('TCL 5 Limit'!C7-'TCL 5 Limit'!C5)*'TCL 5 Limit'!D5 -> #REF! | P4: =O4/'TCL 5 Limit'!D$3 -> #REF! | R4: =B14 -> #REF!
R6: Margin Used
Q8: Market | R8: ='TCL 5 Limit'!C5*'TCL 5 Limit'!D5 -> #REF!
A9: The logic | M9: % TP | N9: New TP | O9: TP Amount | P9: % Accnt
A10: 1 | B10: ='TCL 5 Limit'!D3 -> #REF! | C10: account | F10: 3 | L10: =if('TCL 5 Limit'!F$7>1,'TCL 5 Limit'!G11*($L$3)/'TCL 5 Limit'!$F$7,'TCL 5 Limit'!G11*($L$3)) -> #REF! | M10: =(L10/'TCL 5 Limit'!G11) -> #REF! | N10: =IF('TCL 5 Limit'!B$4="long",'TCL 5 Limit'!G11+L10,'TCL 5 Limit'!G11-L10) -> #REF! | O10: =ABS((N10-'TCL 5 Limit'!G11)*('TCL 5 Limit'!D$5+'TCL 5 Limit'!D11)) -> #REF! | P10: =O10/'TCL 5 Limit'!D$3 -> #REF! | Q10: Limit 1 Cost | R10: ='TCL 5 Limit'!C11*'TCL 5 Limit'!D11 -> #REF!
A11: 2 | B11: 25 | C11: leverage | F11: 5 | L11: =if('TCL 5 Limit'!F$7>1,'TCL 5 Limit'!G12*($L$3)/'TCL 5 Limit'!$F$7,'TCL 5 Limit'!G12*($L$3)) -> #REF! | M11: =(L11/'TCL 5 Limit'!G12) -> #REF! | N11: =IF('TCL 5 Limit'!B$4="long",'TCL 5 Limit'!G12+L11,'TCL 5 Limit'!G12-L11) -> #REF! | O11: =ABS((N11-'TCL 5 Limit'!G12)*('TCL 5 Limit'!D$5+'TCL 5 Limit'!D12+'TCL 5 Limit'!D11)) -> #REF! | P11: =O11/'TCL 5 Limit'!D$3 -> #REF! | Q11: Limit 2 Cost | R11: ='TCL 5 Limit'!C12*'TCL 5 Limit'!D12 -> #REF!
A12: 3 | B12: =B11*B10 -> #REF! | C12: avalable capital | F12: 8 | L12: =if('TCL 5 Limit'!F$7>1,'TCL 5 Limit'!G13*($L$3)/'TCL 5 Limit'!$F$7,'TCL 5 Limit'!G13*($L$3)) -> #REF! | M12: =(L12/'TCL 5 Limit'!G13) -> #REF! | N12: =IF('TCL 5 Limit'!B$4="long",'TCL 5 Limit'!G13+L12,'TCL 5 Limit'!G13-L12) -> #REF! | O12: =ABS((N12-'TCL 5 Limit'!G13)*('TCL 5 Limit'!D$5+'TCL 5 Limit'!D13+'TCL 5 Limit'!D12+'TCL 5 Limit'!D11)) -> #REF! | P12: =O12/'TCL 5 Limit'!D$3 -> #REF! | Q12: Limit 3 Cost | R12: ='TCL 5 Limit'!C13*'TCL 5 Limit'!D13 -> #REF!
A13: 4 | B13: 0.6 | C13: usage to avoid liq | F13: 10 | L13: =if('TCL 5 Limit'!F$7>1,'TCL 5 Limit'!G14*($L$3)/'TCL 5 Limit'!$F$7,'TCL 5 Limit'!G14*($L$3)) -> #REF! | M13: =(L13/'TCL 5 Limit'!G14) -> #REF! | N13: =IF('TCL 5 Limit'!B$4="long",'TCL 5 Limit'!G14+L13,'TCL 5 Limit'!G14-L13) -> #REF! | O13: =ABS((N13-'TCL 5 Limit'!G14)*('TCL 5 Limit'!D$5+'TCL 5 Limit'!D14+'TCL 5 Limit'!D13+'TCL 5 Limit'!D12+'TCL 5 Limit'!D11)) -> #REF! | P13: =O13/'TCL 5 Limit'!D$3 -> #REF! | Q13: Limit 4 Cost | R13: ='TCL 5 Limit'!C14*'TCL 5 Limit'!D14 -> #REF!
A14: 5 | B14: =B13*B12 -> #REF! | C14: capital to use | F14: 15 | L14: =if('TCL 5 Limit'!F$7>1,'TCL 5 Limit'!G15*($L$3)/'TCL 5 Limit'!$F$7,'TCL 5 Limit'!G15*($L$3)) -> #REF! | M14: =(L14/'TCL 5 Limit'!G15) -> #REF! | N14: =IF('TCL 5 Limit'!B$4="long",'TCL 5 Limit'!G15+L14,'TCL 5 Limit'!G15-L14) -> #REF! | O14: =ABS((N14-'TCL 5 Limit'!G15)*('TCL 5 Limit'!D$5+'TCL 5 Limit'!D15+'TCL 5 Limit'!D14+'TCL 5 Limit'!D13+'TCL 5 Limit'!D12+'TCL 5 Limit'!D11)) -> #REF! | P14: =O14/'TCL 5 Limit'!D$3 -> #REF! | Q14: Limit 5 Cost | R14: ='TCL 5 Limit'!C15*'TCL 5 Limit'!D15 -> #REF!
A15: 6 | B15: =sum(F4:F19) -> 42 | C15: pieces | L15: =if('TCL 5 Limit'!F$7>1,'TCL 5 Limit'!F16*($L$3)/'TCL 5 Limit'!$F$7,'TCL 5 Limit'!F16*($L$3)) -> #REF! | M15: =(L15/'TCL 5 Limit'!F16) -> #REF! | N15: =ROUND(IF('TCL 5 Limit'!B$4="long",'TCL 5 Limit'!F16+L15,'TCL 5 Limit'!F16-L15),3) -> #REF! | O15: =ABS((N15-'TCL 5 Limit'!F16)*('TCL 5 Limit'!D$5+'TCL 5 Limit'!D16+'TCL 5 Limit'!D15+'TCL 5 Limit'!D14+'TCL 5 Limit'!D13+'TCL 5 Limit'!D12+'TCL 5 Limit'!D11)) -> #REF! | P15: =O15/'TCL 5 Limit'!D$3 -> #REF! | Q15: Limit 6 Cost | R15: ='TCL 5 Limit'!C16*'TCL 5 Limit'!D16 -> #REF!
A16: 7 | B16: =B14/B15 -> #REF! | C16: capital per chip | N16: =ROUND(IF('TCL 5 Limit'!B$4="long",'TCL 5 Limit'!F17+L16,'TCL 5 Limit'!F17-L16),3) -> #REF! | P16: =O16/'TCL 5 Limit'!D$3 -> #REF! | Q16: Total Position | R16: =SUM(R8:R15) -> #REF!
A17: 8 | B17: =B16/B12 -> #REF! | C17: percentage of available | N17: =ROUND(IF('TCL 5 Limit'!B$4="long",'TCL 5 Limit'!F18+L17,'TCL 5 Limit'!F18-L17),3) -> #REF! | P17: =O17/'TCL 5 Limit'!D$3 -> #REF! | Q17: Margin Used | R17: =R16/R4 -> #REF!
A18: 9 | B18: =B17*0.5 -> #REF! | C18: cut in half for safety | N18: =ROUND(IF('TCL 5 Limit'!B$4="long",'TCL 5 Limit'!F19+L18,'TCL 5 Limit'!F19-L18),3) -> #REF! | P18: =O18/'TCL 5 Limit'!D$3 -> #REF!
A19: 10 | B19: =B18*B12 -> #REF! | C19: per (position) | N19: =ROUND(IF('TCL 5 Limit'!B$4="long",'TCL 5 Limit'!F20+L69,'TCL 5 Limit'!F20-L69),3) -> #REF! | P19: =O19/'TCL 5 Limit'!D$3 -> #REF! | Q19: FINAL AVG COST | R19: =if('TCL 5 Limit'!B4="short",max('TCL 5 Limit'!G11:G20),MIN('TCL 5 Limit'!G11:G20)) -> #REF!
Q20: ACCNT LOSS % | R20: ='TCL 5 Limit'!F8 -> #REF!
Q21: ACCNT LOSS $ | R21: =R20*'TCL 5 Limit'!D3 -> #REF!
Q22: STOP LOSS % | R22: =R21/R16 -> #REF!
Q23: STOP LOSS | R23: =IF('TCL 5 Limit'!B4="short",R19+(R19*R22),R19-(R19*R22)) -> #REF!

Sheet Calculate
A1: 46133 | B1: Market | C1: Close Long | D1: 1304.955 USDT | E1: 9.255 | F1: 141.0 LINK | G1: Trade | H1: 0.3196 | I1: 0.00055 | J1: 46132.491 | K1: 568b1fda
A2: 0.49493056 | B2: -- | C2: Open Long | D2: 1303.122 USDT | E2: 9.242 | F2: 141.0 LINK | G2: Funding | H2: 0.3181 | I2: 1.551e-05 | J2: 46132.417 | K2: f671c05f
A3: USDT | B3: Limit | C3: Open Long | D3: 1296.354 USDT | E3: 9.194 | F3: 141.0 LINK | G3: Trade | H3: 1.758 | I3: 0.0002 | J3: 46132.413 | K3: 127415ab
A4: SOLUSDT | H4: =sum(H1:H3) -> 2.3957
A5: Trade
A6: Close Sell
A7: 33
A8: 0
A9: 85.81
A10: 0
A11: 1.5575 USDT
A12: =+11.55 -> 11.55
A13: =+9.9925 -> 9.9925
A14: 107.3716
A15: Details
A16: 46133
A17: 0.47859954
A18: USDT
A19: SOLUSDT
A20: Trade
A21: Open Buy
A22: 33
A23: 33
A24: 85.46
A25: 0
A26: 0.5640 USDT
A27: 0
A28: -0.564
A29: 97.3791
A30: Details

Sheet DO NOT DELETE
A1: ALL WILL FAIL IF YOU DELETE THIS INFO
A5: Round | B5: Risk Percent | C5: linear and controlled risk tabe - each reference same table, can eliminate one of the phases since tp is the same too
A6: 0.1 | B6: Go Back to Risk Off Phase & Risk 50% | C6: This references the value of trade account divided by starting balance
A7: 0.2 | B7: Go Back to Risk Off Phase & Risk 50%
A8: 0.6 | B8: Go Back to Risk Off Phase & Risk 50%
A9: 0.7 | B9: Go Back to Risk Off Phase & Risk 50%
A10: 1 | B10: 0.5
A11: 1.1 | B11: 0.5
A12: 1.2 | B12: 0.49
A13: 1.3 | B13: 0.48
A14: 1.4 | B14: 0.47
A15: 1.5 | B15: 0.46
A16: 1.7 | B16: 0.45
A17: 1.8 | B17: 0.44
A18: 1.9 | B18: 0.43
A19: 2 | B19: 0.42
A20: 2.2 | B20: 0.41
A21: 2.3 | B21: 0.4
... A79: 19.5 | B79: 0.15537039
